fatal: [ec2-3-144-83-166.us-east-2.compute.amazonaws.com]: FAILED! => {"attempts": 5, "changed": true, 
"msg": "Can't run container automation-eda-init", 
"stderr": "Traceback (most recent call last):\n  File \"/usr/bin/aap-eda-manage\", line 8, in <module>\n    sys.exit(main())\n  
File \"/usr/lib/python3.9/site-packages/aap_eda/manage.py\", line 18, in main\n    execute_from_command_line(sys.argv)\n  
File \"/usr/lib/python3.9/site-packages/django/core/management/__init__.py\", line 442, in execute_from_command_line\n    
utility.execute()\n  File \"/usr/lib/python3.9/site-packages/django/core/management/__init__.py\", line 416, in execute\n   
 django.setup()\n  File \"/usr/lib/python3.9/site-packages/django/__init__.py\", line 24, in setup\n    
 apps.populate(settings.INSTALLED_APPS)\n  File \"/usr/lib/python3.9/site-packages/django/apps/registry.py\", line 116, in populate\n    
 app_config.import_models()\n  File \"/usr/lib/python3.9/site-packages/django/apps/config.py\", line 269, in import_models\n    
 self.models_module = import_module(models_module_name)\n  File \"/usr/lib64/python3.9/importlib/__init__.py\", line 127, in import_module\n 
    return _bootstrap._gcd_import(name[level:], package, level)\n  File \"<frozen importlib._bootstrap>\", line 1030, in _gcd_import\n 
     File \"<frozen importlib._bootstrap>\", line 1007, in _find_and_load\n  File \"<frozen importlib._bootstrap>\", line 986, in _find_and_load_unlocked\n  
     File \"<frozen importlib._bootstrap>\", line 680, in _load_unlocked\n  File \"<frozen importlib._bootstrap_external>\", line 850, in exec_module\n  
     File \"<frozen importlib._bootstrap>\", line 228, in _call_with_frames_removed\n  
     File \"/usr/lib/python3.9/site-packages/ansible_base/authentication/models/__init__.py\", line 3, in <module>\n    
     from .social_auth import AuthenticatorUser\n  File \"/usr/lib/python3.9/site-packages/ansible_base/authentication/models/social_auth.py\", 
     line 3, in <module>\n    from social_django.models import AbstractUserSocialAuth\n  File \"/usr/lib/python3.9/site-packages/social_django/__init__.py\", 
     line 4, in <module>\n    from social_core.backends.base import BaseAuth\n  File \"/usr/lib/python3.9/site-packages/social_core/backends/base.py\", 
     line 3, in <module>\n    from requests import ConnectionError, request\n  File \"/usr/lib/python3.9/site-packages/requests/__init__.py\", 
     line 164, in <module>\n    from .api import delete, get, head, options, patch, post, put, request\n  
     File \"/usr/lib/python3.9/site-packages/requests/api.py\", line 11, in <module>\n    
     from . import sessions\n  File \"/usr/lib/python3.9/site-packages/requests/sessions.py\", line 15, in <module>\n    
     from .adapters import HTTPAdapter\n  File \"/usr/lib/python3.9/site-packages/requests/adapters.py\", line 77, in <module>\n    
     _preloaded_ssl_context.load_verify_locations(\nPermissionError: [Errno 13] Permission denied\n", 
     "stderr_lines": ["Traceback (most recent call last):", "  File \"/usr/bin/aap-eda-manage\", line 8, in <module>", "    
     sys.exit(main())", "  File \"/usr/lib/python3.9/site-packages/aap_eda/manage.py\", line 18, in main", "    execute_from_command_line(sys.argv)", 
     "  File \"/usr/lib/python3.9/site-packages/django/core/management/__init__.py\", line 442, in execute_from_command_line", "    utility.execute()", " 
      File \"/usr/lib/python3.9/site-packages/django/core/management/__init__.py\", line 416, in execute", "    django.setup()", " 
       File \"/usr/lib/python3.9/site-packages/django/__init__.py\", line 24, in setup", "    apps.populate(settings.INSTALLED_APPS)", " 
        File \"/usr/lib/python3.9/site-packages/django/apps/registry.py\", line 116, in populate", "    app_config.import_models()", "  
        File \"/usr/lib/python3.9/site-packages/django/apps/config.py\", line 269, in import_models", "    
        self.models_module = import_module(models_module_name)", "  File \"/usr/lib64/python3.9/importlib/__init__.py\", line 127, in import_module", "    
        return _bootstrap._gcd_import(name[level:], package, level)", "  File \"<frozen importlib._bootstrap>\", line 1030, in _gcd_import", "  
        File \"<frozen importlib._bootstrap>\", line 1007, in _find_and_load", 
        "  File \"<frozen importlib._bootstrap>\", line 986, in _find_and_load_unlocked", 
        "  File \"<frozen importlib._bootstrap>\", line 680, in _load_unlocked", 
    "  File \"<frozen importlib._bootstrap_external>\", line 850, in exec_module", "  
    File \"<frozen importlib._bootstrap>\", line 228, in _call_with_frames_removed", "  
    File \"/usr/lib/python3.9/site-packages/ansible_base/authentication/models/__init__.py\", line 3, 
    in <module>", "    from .social_auth import AuthenticatorUser", "  
    File \"/usr/lib/python3.9/site-packages/ansible_base/authentication/models/social_auth.py\", 
    line 3, in <module>", "    from social_django.models import AbstractUserSocialAuth", "  
    File \"/usr/lib/python3.9/site-packages/social_django/__init__.py\", line 4, in <module>", "   
     from social_core.backends.base import BaseAuth", "  
     File \"/usr/lib/python3.9/site-packages/social_core/backends/base.py\", line 3, in <module>", "   
      from requests import ConnectionError, request", " 
       File \"/usr/lib/python3.9/site-packages/requests/__init__.py\", line 164, in <module>", "   
        from .api import delete, get, head, options, patch, post, put, request", " 
         File \"/usr/lib/python3.9/site-packages/requests/api.py\", line 11, in <module>", "   
          from . import sessions", "  File \"/usr/lib/python3.9/site-packages/requests/sessions.py\", line 15, 
          in <module>", "    from .adapters import HTTPAdapter", " 
           File \"/usr/lib/python3.9/site-packages/requests/adapters.py\", line 77, in <module>", "  
             _preloaded_ssl_context.load_verify_locations(", "PermissionError: [Errno 13] Permission denied"], 
             "stdout": "", "stdout_lines": []}
             

NO MORE HOSTS LEFT 